Workbook

Sheet Sheet3
A1: الرمز | B1: اسم الشركة (قصير) | C1: اسم الشركة (طويل) | D1: القطاع | E1: الإقفال السابق | F1: سعر الفتح | G1: اخر سعر | H1: التغير % | I1: آخر | J1: عالي | K1: منخفض | L1: القيمة (جنيه) | M1: الحجم | N1: عدد العمليات | O1: رأس المال السوقى (مليون جنيه)
A2: ACAP | B2: =C2 -> اية كابيتال القابضة | C2: =VLOOKUP(A2,Sheet1!C:F,2,0) -> اية كابيتال القابضة | D2: عقارات | E2: =VLOOKUP(C2,Sheet2!A:N,4,0) -> 9.2 | F2: =VLOOKUP(C2,Sheet2!A:N,5,0) -> 9.2 | G2: =VLOOKUP(C2,Sheet2!A:N,6,0) -> 9.06 | H2: =VLOOKUP(C2,Sheet2!A:N,7,0) -> -1.52 | I2: =VLOOKUP(C2,Sheet2!A:N,8,0) -> 9.06 | J2: =VLOOKUP(C2,Sheet2!A:N,9,0) -> 9.39 | K2: =VLOOKUP(C2,Sheet2!A:N,10,0) -> 9.02 | L2: =VLOOKUP(C2,Sheet2!A:N,11,0) -> 5567868.9 | M2: =VLOOKUP(C2,Sheet2!A:N,12,0) -> 605796 | N2: =VLOOKUP(C2,Sheet2!A:N,13,0) -> 447 | O2: =VLOOKUP(C2,Sheet2!A:N,14,0) -> 6625
A3: TAQA | B3: =C3 -> طاقة عربية | C3: =VLOOKUP(A3,Sheet1!C:F,2,0) -> طاقة عربية | D3: مرافق | E3: =VLOOKUP(C3,Sheet2!A:N,4,0) -> 15.6 | F3: =VLOOKUP(C3,Sheet2!A:N,5,0) -> 15.6 | G3: =VLOOKUP(C3,Sheet2!A:N,6,0) -> 15.3 | H3: =VLOOKUP(C3,Sheet2!A:N,7,0) -> -1.92 | I3: =VLOOKUP(C3,Sheet2!A:N,8,0) -> 15.3 | J3: =VLOOKUP(C3,Sheet2!A:N,9,0) -> 15.69 | K3: =VLOOKUP(C3,Sheet2!A:N,10,0) -> 15.13 | L3: =VLOOKUP(C3,Sheet2!A:N,11,0) -> 68089318 | M3: =VLOOKUP(C3,Sheet2!A:N,12,0) -> 4436058 | N3: =VLOOKUP(C3,Sheet2!A:N,13,0) -> 2110 | O3: =VLOOKUP(C3,Sheet2!A:N,14,0) -> 20691
A4: NAPR | B4: =C4 -> الوطنية للطباعة | C4: =VLOOKUP(A4,Sheet1!C:F,2,0) -> الوطنية للطباعة | D4: ورق ومواد تعبئة و تغليف | E4: =VLOOKUP(C4,Sheet2!A:N,4,0) -> 25.02 | F4: =VLOOKUP(C4,Sheet2!A:N,5,0) -> 25.02 | G4: =VLOOKUP(C4,Sheet2!A:N,6,0) -> 25.87 | H4: =VLOOKUP(C4,Sheet2!A:N,7,0) -> 3.4 | I4: =VLOOKUP(C4,Sheet2!A:N,8,0) -> 25.9 | J4: =VLOOKUP(C4,Sheet2!A:N,9,0) -> 26 | K4: =VLOOKUP(C4,Sheet2!A:N,10,0) -> 25.1 | L4: =VLOOKUP(C4,Sheet2!A:N,11,0) -> 559078.21 | M4: =VLOOKUP(C4,Sheet2!A:N,12,0) -> 21620 | N4: =VLOOKUP(C4,Sheet2!A:N,13,0) -> 30 | O4: =VLOOKUP(C4,Sheet2!A:N,14,0) -> 5571
A5: ACTF | B5: =C5 -> اكت فاينانشال للاستشارات | C5: =VLOOKUP(A5,Sheet1!C:F,2,0) -> اكت فاينانشال للاستشارات | D5: خدمات مالية غير مصرفية | E5: =VLOOKUP(C5,Sheet2!A:N,4,0) -> 2.71 | F5: =VLOOKUP(C5,Sheet2!A:N,5,0) -> 2.71 | G5: =VLOOKUP(C5,Sheet2!A:N,6,0) -> 2.72 | H5: =VLOOKUP(C5,Sheet2!A:N,7,0) -> 0.37 | I5: =VLOOKUP(C5,Sheet2!A:N,8,0) -> 2.72 | J5: =VLOOKUP(C5,Sheet2!A:N,9,0) -> 2.74 | K5: =VLOOKUP(C5,Sheet2!A:N,10,0) -> 2.71 | L5: =VLOOKUP(C5,Sheet2!A:N,11,0) -> 5141239 | M5: =VLOOKUP(C5,Sheet2!A:N,12,0) -> 1887396 | N5: =VLOOKUP(C5,Sheet2!A:N,13,0) -> 222 | O5: =VLOOKUP(C5,Sheet2!A:N,14,0) -> 3108
A6: MBEG | B6: =C6 -> أم بي للهندسةM.B | C6: =VLOOKUP(A6,Sheet1!C:F,2,0) -> أم بي للهندسةM.B | D6: خدمات و منتجات صناعية وسيارات | E6: =VLOOKUP(C6,Sheet2!A:N,4,0) -> 3.73 | F6: =VLOOKUP(C6,Sheet2!A:N,5,0) -> 3.73 | G6: =VLOOKUP(C6,Sheet2!A:N,6,0) -> 3.67 | H6: =VLOOKUP(C6,Sheet2!A:N,7,0) -> -1.61 | I6: =VLOOKUP(C6,Sheet2!A:N,8,0) -> 3.67 | J6: =VLOOKUP(C6,Sheet2!A:N,9,0) -> 3.75 | K6: =VLOOKUP(C6,Sheet2!A:N,10,0) -> 3.66 | L6: =VLOOKUP(C6,Sheet2!A:N,11,0) -> 1639457.8 | M6: =VLOOKUP(C6,Sheet2!A:N,12,0) -> 443936 | N6: =VLOOKUP(C6,Sheet2!A:N,13,0) -> 134 | O6: =VLOOKUP(C6,Sheet2!A:N,14,0) -> 743
A7: LUTS | B7: =C7 -> لوتس للتنمية والاستثمار الزراعى | C7: =VLOOKUP(A7,Sheet1!C:F,2,0) -> لوتس للتنمية والاستثمار الزراعى | D7: أغذية و مشروبات و تبغ | E7: =VLOOKUP(C7,Sheet2!A:N,4,0) -> 0.752 | F7: =VLOOKUP(C7,Sheet2!A:N,5,0) -> 0.752 | G7: =VLOOKUP(C7,Sheet2!A:N,6,0) -> 0.737 | H7: =VLOOKUP(C7,Sheet2!A:N,7,0) -> -1.99 | I7: =VLOOKUP(C7,Sheet2!A:N,8,0) -> 0.737 | J7: =VLOOKUP(C7,Sheet2!A:N,9,0) -> 0.771 | K7: =VLOOKUP(C7,Sheet2!A:N,10,0) -> 0.732 | L7: =VLOOKUP(C7,Sheet2!A:N,11,0) -> 52499263 | M7: =VLOOKUP(C7,Sheet2!A:N,12,0) -> 70138166 | N7: =VLOOKUP(C7,Sheet2!A:N,13,0) -> 1698 | O7: =VLOOKUP(C7,Sheet2!A:N,14,0) -> 774
A8: UBEE | B8: =C8 -> المصرف المتحد | C8: =VLOOKUP(A8,Sheet1!C:F,2,0) -> المصرف المتحد | D8: بنوك | E8: =VLOOKUP(C8,Sheet2!A:N,4,0) -> 13.92 | F8: =VLOOKUP(C8,Sheet2!A:N,5,0) -> 13.92 | G8: =VLOOKUP(C8,Sheet2!A:N,6,0) -> 13.93 | H8: =VLOOKUP(C8,Sheet2!A:N,7,0) -> 0.07 | I8: =VLOOKUP(C8,Sheet2!A:N,8,0) -> 13.93 | J8: =VLOOKUP(C8,Sheet2!A:N,9,0) -> 14.1 | K8: =VLOOKUP(C8,Sheet2!A:N,10,0) -> 13.92 | L8: =VLOOKUP(C8,Sheet2!A:N,11,0) -> 4345580.9 | M8: =VLOOKUP(C8,Sheet2!A:N,12,0) -> 310858 | N8: =VLOOKUP(C8,Sheet2!A:N,13,0) -> 199 | O8: =VLOOKUP(C8,Sheet2!A:N,14,0) -> 15323
A9: AIDC | B9: =C9 -> ارابيا للاستثمار والتنمية | C9: =VLOOKUP(A9,Sheet1!C:F,2,0) -> ارابيا للاستثمار والتنمية | D9: خدمات مالية غير مصرفية | E9: =VLOOKUP(C9,Sheet2!A:N,4,0) -> 0.677 | F9: =VLOOKUP(C9,Sheet2!A:N,5,0) -> 0.677 | G9: =VLOOKUP(C9,Sheet2!A:N,6,0) -> 0.66 | H9: =VLOOKUP(C9,Sheet2!A:N,7,0) -> -2.51 | I9: =VLOOKUP(C9,Sheet2!A:N,8,0) -> 0.66 | J9: =VLOOKUP(C9,Sheet2!A:N,9,0) -> 0.686 | K9: =VLOOKUP(C9,Sheet2!A:N,10,0) -> 0.654 | L9: =VLOOKUP(C9,Sheet2!A:N,11,0) -> 8992505.3 | M9: =VLOOKUP(C9,Sheet2!A:N,12,0) -> 13410501 | N9: =VLOOKUP(C9,Sheet2!A:N,13,0) -> 339 | O9: =VLOOKUP(C9,Sheet2!A:N,14,0) -> 1028
A10: PHGC | B10: =C10 -> بريميم هيلثكير جروب | C10: =VLOOKUP(A10,Sheet1!C:F,2,0) -> بريميم هيلثكير جروب | D10: رعاية صحية و ادوية | E10: =VLOOKUP(C10,Sheet2!A:N,4,0) -> 0.092 | F10: =VLOOKUP(C10,Sheet2!A:N,5,0) -> 0.092 | G10: =VLOOKUP(C10,Sheet2!A:N,6,0) -> 0.09 | H10: =VLOOKUP(C10,Sheet2!A:N,7,0) -> -2.17 | I10: =VLOOKUP(C10,Sheet2!A:N,8,0) -> 0.09 | J10: =VLOOKUP(C10,Sheet2!A:N,9,0) -> 0.094 | K10: =VLOOKUP(C10,Sheet2!A:N,10,0) -> 0.09 | L10: =VLOOKUP(C10,Sheet2!A:N,11,0) -> 28937462 | M10: =VLOOKUP(C10,Sheet2!A:N,12,0) -> 317498763 | N10: =VLOOKUP(C10,Sheet2!A:N,13,0) -> 785 | O10: =VLOOKUP(C10,Sheet2!A:N,14,0) -> 2127
A11: BONY | B11: =C11 -> بنيان للتنمية والتجارة | C11: =VLOOKUP(A11,Sheet1!C:F,2,0) -> بنيان للتنمية والتجارة | D11: عقارات | E11: =VLOOKUP(C11,Sheet2!A:N,4,0) -> 5.26 | F11: =VLOOKUP(C11,Sheet2!A:N,5,0) -> 5.26 | G11: =VLOOKUP(C11,Sheet2!A:N,6,0) -> 5.35 | H11: =VLOOKUP(C11,Sheet2!A:N,7,0) -> 1.71 | I11: =VLOOKUP(C11,Sheet2!A:N,8,0) -> 5.35 | J11: =VLOOKUP(C11,Sheet2!A:N,9,0) -> 5.48 | K11: =VLOOKUP(C11,Sheet2!A:N,10,0) -> 5.15 | L11: =VLOOKUP(C11,Sheet2!A:N,11,0) -> 1.591459e+08 | M11: =VLOOKUP(C11,Sheet2!A:N,12,0) -> 30328220 | N11: =VLOOKUP(C11,Sheet2!A:N,13,0) -> 1833 | O11: =VLOOKUP(C11,Sheet2!A:N,14,0) -> 9119
A12: ICFC | B12: =C12 -> الدولية للأسمدة والكيماويات | C12: =VLOOKUP(A12,Sheet1!C:F,2,0) -> الدولية للأسمدة والكيماويات | D12: تجارة و موزعون | E12: =VLOOKUP(C12,Sheet2!A:N,4,0) -> 15.05 | F12: =VLOOKUP(C12,Sheet2!A:N,5,0) -> 15.05 | G12: =VLOOKUP(C12,Sheet2!A:N,6,0) -> 15.14 | H12: =VLOOKUP(C12,Sheet2!A:N,7,0) -> 0.6 | I12: =VLOOKUP(C12,Sheet2!A:N,8,0) -> 15.14 | J12: =VLOOKUP(C12,Sheet2!A:N,9,0) -> 15.21 | K12: =VLOOKUP(C12,Sheet2!A:N,10,0) -> 15.01 | L12: =VLOOKUP(C12,Sheet2!A:N,11,0) -> 2813156.8 | M12: =VLOOKUP(C12,Sheet2!A:N,12,0) -> 186499 | N12: =VLOOKUP(C12,Sheet2!A:N,13,0) -> 180 | O12: =VLOOKUP(C12,Sheet2!A:N,14,0) -> 1768
A13: GOUR | B13: =C13 -> جورميه ايجيبت دوت كوم للاغذية | C13: =VLOOKUP(A13,Sheet1!C:F,2,0) -> جورميه ايجيبت دوت كوم للاغذية | D13: تجارة و موزعون | E13: =VLOOKUP(C13,Sheet2!A:N,4,0) -> 12.79 | F13: =VLOOKUP(C13,Sheet2!A:N,5,0) -> 12.79 | G13: =VLOOKUP(C13,Sheet2!A:N,6,0) -> 12.7 | H13: =VLOOKUP(C13,Sheet2!A:N,7,0) -> -0.7 | I13: =VLOOKUP(C13,Sheet2!A:N,8,0) -> 12.7 | J13: =VLOOKUP(C13,Sheet2!A:N,9,0) -> 12.88 | K13: =VLOOKUP(C13,Sheet2!A:N,10,0) -> 12.6 | L13: =VLOOKUP(C13,Sheet2!A:N,11,0) -> 28203630 | M13: =VLOOKUP(C13,Sheet2!A:N,12,0) -> 2230803 | N13: =VLOOKUP(C13,Sheet2!A:N,13,0) -> 529 | O13: =VLOOKUP(C13,Sheet2!A:N,14,0) -> 5080
... A142: ECAP | B142: =C142 -> العز للسيراميك و البورسلين - الجوهره | C142: =VLOOKUP(A142,Sheet1!C:F,2,0) -> العز للسيراميك و البورسلين - الجوهره | D142: مواد البناء | E142: =VLOOKUP(C142,Sheet2!A:N,4,0) -> 31.77 | F142: =VLOOKUP(C142,Sheet2!A:N,5,0) -> 31.77 | G142: =VLOOKUP(C142,Sheet2!A:N,6,0) -> 32.56 | H142: =VLOOKUP(C142,Sheet2!A:N,7,0) -> 2.49 | I142: =VLOOKUP(C142,Sheet2!A:N,8,0) -> 32.56 | J142: =VLOOKUP(C142,Sheet2!A:N,9,0) -> 32.62 | K142: =VLOOKUP(C142,Sheet2!A:N,10,0) -> 31.3 | L142: =VLOOKUP(C142,Sheet2!A:N,11,0) -> 8863962.1 | M142: =VLOOKUP(C142,Sheet2!A:N,12,0) -> 274400 | N142: =VLOOKUP(C142,Sheet2!A:N,13,0) -> 297 | O142: =VLOOKUP(C142,Sheet2!A:N,14,0) -> 1737
A143: CERA | B143: =C143 -> العربية للخزف - سيراميكا ريماس | C143: =VLOOKUP(A143,Sheet1!C:F,2,0) -> العربية للخزف - سيراميكا ريماس | D143: مواد البناء | E143: =VLOOKUP(C143,Sheet2!A:N,4,0) -> 1.18 | F143: =VLOOKUP(C143,Sheet2!A:N,5,0) -> 1.18 | G143: =VLOOKUP(C143,Sheet2!A:N,8,0) -> 1.29 | H143: =VLOOKUP(C143,Sheet2!A:N,7,0) -> 9.32 | I143: =VLOOKUP(C143,Sheet2!A:N,8,0) -> 1.29 | J143: =VLOOKUP(C143,Sheet2!A:N,9,0) -> 1.3 | K143: =VLOOKUP(C143,Sheet2!A:N,10,0) -> 1.17 | L143: =VLOOKUP(C143,Sheet2!A:N,11,0) -> 79653620 | M143: =VLOOKUP(C143,Sheet2!A:N,12,0) -> 63324912 | N143: =VLOOKUP(C143,Sheet2!A:N,13,0) -> 1523 | O143: =VLOOKUP(C143,Sheet2!A:N,14,0) -> 1391
A144: SCEM | B144: =C144 -> اسمنت سيناء | C144: =VLOOKUP(A144,Sheet1!C:F,2,0) -> اسمنت سيناء | D144: مواد البناء | E144: =VLOOKUP(C144,Sheet2!A:N,4,0) -> 62.06 | F144: =VLOOKUP(C144,Sheet2!A:N,5,0) -> 62.06 | G144: =VLOOKUP(C144,Sheet2!A:N,6,0) -> 62.18 | H144: =VLOOKUP(C144,Sheet2!A:N,7,0) -> 0.19 | I144: =VLOOKUP(C144,Sheet2!A:N,8,0) -> 62.18 | J144: =VLOOKUP(C144,Sheet2!A:N,9,0) -> 62.37 | K144: =VLOOKUP(C144,Sheet2!A:N,10,0) -> 61.5 | L144: =VLOOKUP(C144,Sheet2!A:N,11,0) -> 20510871 | M144: =VLOOKUP(C144,Sheet2!A:N,12,0) -> 331112 | N144: =VLOOKUP(C144,Sheet2!A:N,13,0) -> 281 | O144: =VLOOKUP(C144,Sheet2!A:N,14,0) -> 16217
A145: MBSC | B145: =C145 -> مصر بنى سويف للاسمنت | C145: =VLOOKUP(A145,Sheet1!C:F,2,0) -> مصر بنى سويف للاسمنت | D145: مواد البناء | E145: =VLOOKUP(C145,Sheet2!A:N,4,0) -> 271.52 | F145: =VLOOKUP(C145,Sheet2!A:N,5,0) -> 271.52 | G145: =VLOOKUP(C145,Sheet2!A:N,6,0) -> 251.92 | H145: =VLOOKUP(C145,Sheet2!A:N,7,0) -> -7.22 | I145: =VLOOKUP(C145,Sheet2!A:N,8,0) -> 251.92 | J145: =VLOOKUP(C145,Sheet2!A:N,9,0) -> 254.99 | K145: =VLOOKUP(C145,Sheet2!A:N,10,0) -> 251.57 | L145: =VLOOKUP(C145,Sheet2!A:N,11,0) -> 35958353 | M145: =VLOOKUP(C145,Sheet2!A:N,12,0) -> 142152 | N145: =VLOOKUP(C145,Sheet2!A:N,13,0) -> 1507 | O145: =VLOOKUP(C145,Sheet2!A:N,14,0) -> 13861
A146: SVCE | B146: =C146 -> جنوب الوادى للاسمنت | C146: =VLOOKUP(A146,Sheet1!C:F,2,0) -> جنوب الوادى للاسمنت | D146: مواد البناء | E146: =VLOOKUP(C146,Sheet2!A:N,4,0) -> 9.16 | F146: =VLOOKUP(C146,Sheet2!A:N,5,0) -> 9.16 | G146: =VLOOKUP(C146,Sheet2!A:N,6,0) -> 9.02 | H146: =VLOOKUP(C146,Sheet2!A:N,7,0) -> -1.53 | I146: =VLOOKUP(C146,Sheet2!A:N,8,0) -> 9.02 | J146: =VLOOKUP(C146,Sheet2!A:N,9,0) -> 9.29 | K146: =VLOOKUP(C146,Sheet2!A:N,10,0) -> 9 | L146: =VLOOKUP(C146,Sheet2!A:N,11,0) -> 85696028 | M146: =VLOOKUP(C146,Sheet2!A:N,12,0) -> 9371974 | N146: =VLOOKUP(C146,Sheet2!A:N,13,0) -> 2004 | O146: =VLOOKUP(C146,Sheet2!A:N,14,0) -> 4350
A147: SUGR | B147: =C147 -> الدلتا للسكر | C147: =VLOOKUP(A147,Sheet1!C:F,2,0) -> الدلتا للسكر | D147: أغذية و مشروبات و تبغ | E147: =VLOOKUP(C147,Sheet2!A:N,4,0) -> 48.54 | F147: =VLOOKUP(C147,Sheet2!A:N,5,0) -> 48.54 | G147: =VLOOKUP(C147,Sheet2!A:N,6,0) -> 48.64 | H147: =VLOOKUP(C147,Sheet2!A:N,7,0) -> 0.21 | I147: =VLOOKUP(C147,Sheet2!A:N,8,0) -> 48.78 | J147: =VLOOKUP(C147,Sheet2!A:N,9,0) -> 48.87 | K147: =VLOOKUP(C147,Sheet2!A:N,10,0) -> 48.41 | L147: =VLOOKUP(C147,Sheet2!A:N,11,0) -> 3080752.8 | M147: =VLOOKUP(C147,Sheet2!A:N,12,0) -> 63373 | N147: =VLOOKUP(C147,Sheet2!A:N,13,0) -> 173 | O147: =VLOOKUP(C147,Sheet2!A:N,14,0) -> 6917
A148: SNFC | B148: =C148 -> الشرقية الوطنية للامن الغذائي | C148: =VLOOKUP(A148,Sheet1!C:F,2,0) -> الشرقية الوطنية للامن الغذائي | D148: أغذية و مشروبات و تبغ | E148: =VLOOKUP(C148,Sheet2!A:N,4,0) -> 12.39 | F148: =VLOOKUP(C148,Sheet2!A:N,5,0) -> 12.39 | G148: =VLOOKUP(C148,Sheet2!A:N,6,0) -> 12.36 | H148: =VLOOKUP(C148,Sheet2!A:N,7,0) -> -0.24 | I148: =VLOOKUP(C148,Sheet2!A:N,8,0) -> 12.37 | J148: =VLOOKUP(C148,Sheet2!A:N,9,0) -> 12.39 | K148: =VLOOKUP(C148,Sheet2!A:N,10,0) -> 12.19 | L148: =VLOOKUP(C148,Sheet2!A:N,11,0) -> 5251659.5 | M148: =VLOOKUP(C148,Sheet2!A:N,12,0) -> 428142 | N148: =VLOOKUP(C148,Sheet2!A:N,13,0) -> 164 | O148: =VLOOKUP(C148,Sheet2!A:N,14,0) -> 2026
A149: FAIT | B149: =C149 -> بنك فيصل الاسلامي المصرية بالجنية | C149: =VLOOKUP(A149,Sheet1!C:F,2,0) -> بنك فيصل الاسلامي المصرية بالجنية | D149: بنوك | E149: =VLOOKUP(C149,Sheet2!A:N,4,0) -> 37.42 | F149: =VLOOKUP(C149,Sheet2!A:N,5,0) -> 37.42 | G149: =VLOOKUP(C149,Sheet2!A:N,6,0) -> 37.21 | H149: =VLOOKUP(C149,Sheet2!A:N,7,0) -> -0.56 | I149: =VLOOKUP(C149,Sheet2!A:N,8,0) -> 37.01 | J149: =VLOOKUP(C149,Sheet2!A:N,9,0) -> 37.42 | K149: =VLOOKUP(C149,Sheet2!A:N,10,0) -> 36.05 | L149: =VLOOKUP(C149,Sheet2!A:N,11,0) -> 1377505 | M149: =VLOOKUP(C149,Sheet2!A:N,12,0) -> 37158 | N149: =VLOOKUP(C149,Sheet2!A:N,13,0) -> 124 | O149: =VLOOKUP(C149,Sheet2!A:N,14,0) -> 8406
A150: RREI | B150: =C150 -> الاستثمار العقاري العربي - اليكو | C150: =VLOOKUP(A150,Sheet1!C:F,2,0) -> الاستثمار العقاري العربي - اليكو | D150: عقارات | E150: =VLOOKUP(C150,Sheet2!A:N,4,0) -> 3.5 | F150: =VLOOKUP(C150,Sheet2!A:N,5,0) -> 3.5 | G150: =VLOOKUP(C150,Sheet2!A:N,6,0) -> 3.65 | H150: =VLOOKUP(C150,Sheet2!A:N,7,0) -> 4.29 | I150: =VLOOKUP(C150,Sheet2!A:N,8,0) -> 3.65 | J150: =VLOOKUP(C150,Sheet2!A:N,9,0) -> 3.67 | K150: =VLOOKUP(C150,Sheet2!A:N,10,0) -> 3.52 | L150: =VLOOKUP(C150,Sheet2!A:N,11,0) -> 40623263 | M150: =VLOOKUP(C150,Sheet2!A:N,12,0) -> 11241504 | N150: =VLOOKUP(C150,Sheet2!A:N,13,0) -> 927 | O150: =VLOOKUP(C150,Sheet2!A:N,14,0) -> 899
A151: AFDI | B151: =C151 -> الاهلي للتنمية والاستثمار | C151: =VLOOKUP(A151,Sheet1!C:F,2,0) -> الاهلي للتنمية والاستثمار | D151: خدمات مالية غير مصرفية | E151: =VLOOKUP(C151,Sheet2!A:N,4,0) -> 42.97 | F151: =VLOOKUP(C151,Sheet2!A:N,5,0) -> 42.97 | G151: =VLOOKUP(C151,Sheet2!A:N,6,0) -> 42.8 | H151: =VLOOKUP(C151,Sheet2!A:N,7,0) -> -0.4 | I151: =VLOOKUP(C151,Sheet2!A:N,8,0) -> 42.8 | J151: =VLOOKUP(C151,Sheet2!A:N,9,0) -> 43.4 | K151: =VLOOKUP(C151,Sheet2!A:N,10,0) -> 42.01 | L151: =VLOOKUP(C151,Sheet2!A:N,11,0) -> 5577093.3 | M151: =VLOOKUP(C151,Sheet2!A:N,12,0) -> 130834 | N151: =VLOOKUP(C151,Sheet2!A:N,13,0) -> 158 | O151: =VLOOKUP(C151,Sheet2!A:N,14,0) -> 770
A152: KWIN | B152: =C152 -> القاهرة الوطنية للاستثمار والاوراق المالية | C152: =VLOOKUP(A152,Sheet1!C:F,2,0) -> القاهرة الوطنية للاستثمار والاوراق المالية | D152: خدمات مالية غير مصرفية | E152: =VLOOKUP(C152,Sheet2!A:N,4,0) -> 75.04 | F152: =VLOOKUP(C152,Sheet2!A:N,5,0) -> 75.04 | G152: =VLOOKUP(C152,Sheet2!A:N,6,0) -> 74.15 | H152: =VLOOKUP(C152,Sheet2!A:N,7,0) -> -1.19 | I152: =VLOOKUP(C152,Sheet2!A:N,8,0) -> 74.15 | J152: =VLOOKUP(C152,Sheet2!A:N,9,0) -> 75.98 | K152: =VLOOKUP(C152,Sheet2!A:N,10,0) -> 72.5 | L152: =VLOOKUP(C152,Sheet2!A:N,11,0) -> 5380090.5 | M152: =VLOOKUP(C152,Sheet2!A:N,12,0) -> 72700 | N152: =VLOOKUP(C152,Sheet2!A:N,13,0) -> 235 | O152: =VLOOKUP(C152,Sheet2!A:N,14,0) -> 779
A153: NHPS | B153: =C153 -> الوطنية للاسكان للنقابات المهنية | C153: =VLOOKUP(A153,Sheet1!C:F,2,0) -> الوطنية للاسكان للنقابات المهنية | D153: عقارات | E153: =VLOOKUP(C153,Sheet2!A:N,4,0) -> 67.72 | F153: =VLOOKUP(C153,Sheet2!A:N,5,0) -> 67.72 | G153: =VLOOKUP(C153,Sheet2!A:N,6,0) -> 68.07 | H153: =VLOOKUP(C153,Sheet2!A:N,7,0) -> 0.52 | I153: =VLOOKUP(C153,Sheet2!A:N,8,0) -> 68.07 | J153: =VLOOKUP(C153,Sheet2!A:N,9,0) -> 69 | K153: =VLOOKUP(C153,Sheet2!A:N,10,0) -> 68 | L153: =VLOOKUP(C153,Sheet2!A:N,11,0) -> 2959701.5 | M153: =VLOOKUP(C153,Sheet2!A:N,12,0) -> 43310 | N153: =VLOOKUP(C153,Sheet2!A:N,13,0) -> 167 | O153: =VLOOKUP(C153,Sheet2!A:N,14,0) -> 1089
A154: DAPH | B154: =C154 -> التعمير والاستشارات الهندسية | C154: =VLOOKUP(A154,Sheet1!C:F,2,0) -> التعمير والاستشارات الهندسية | D154: عقارات | E154: =VLOOKUP(C154,Sheet2!A:N,4,0) -> 77.72 | F154: =VLOOKUP(C154,Sheet2!A:N,5,0) -> 77.72 | G154: =VLOOKUP(C154,Sheet2!A:N,6,0) -> 81.26 | H154: =VLOOKUP(C154,Sheet2!A:N,7,0) -> 4.55 | I154: =VLOOKUP(C154,Sheet2!A:N,8,0) -> 81.26 | J154: =VLOOKUP(C154,Sheet2!A:N,9,0) -> 82 | K154: =VLOOKUP(C154,Sheet2!A:N,10,0) -> 77.52 | L154: =VLOOKUP(C154,Sheet2!A:N,11,0) -> 11660051 | M154: =VLOOKUP(C154,Sheet2!A:N,12,0) -> 144658 | N154: =VLOOKUP(C154,Sheet2!A:N,13,0) -> 428 | O154: =VLOOKUP(C154,Sheet2!A:N,14,0) -> 1911
A155: ELKA | B155: =C155 -> القاهرة للاسكان والتعمير | C155: =VLOOKUP(A155,Sheet1!C:F,2,0) -> القاهرة للاسكان والتعمير | D155: عقارات | E155: =VLOOKUP(C155,Sheet2!A:N,4,0) -> 1.27 | F155: =VLOOKUP(C155,Sheet2!A:N,5,0) -> 1.27 | G155: =VLOOKUP(C155,Sheet2!A:N,6,0) -> 1.32 | H155: =VLOOKUP(C155,Sheet2!A:N,7,0) -> 3.94 | I155: =VLOOKUP(C155,Sheet2!A:N,8,0) -> 1.32 | J155: =VLOOKUP(C155,Sheet2!A:N,9,0) -> 1.32 | K155: =VLOOKUP(C155,Sheet2!A:N,10,0) -> 1.26 | L155: =VLOOKUP(C155,Sheet2!A:N,11,0) -> 57681699 | M155: =VLOOKUP(C155,Sheet2!A:N,12,0) -> 44426700 | N155: =VLOOKUP(C155,Sheet2!A:N,13,0) -> 1338 | O155: =VLOOKUP(C155,Sheet2!A:N,14,0) -> 2451
... A205: TALM | B205: =C205 -> Taaleem Management Services تعليم لخدمات الإدارة | C205: =VLOOKUP(A205,Sheet1!C:F,2,0) -> Taaleem Management Services تعليم لخدمات الإدارة | D205: خدمات تعليمية | E205: =VLOOKUP(C205,Sheet2!A:N,4,0) -> 16.12 | F205: =VLOOKUP(C205,Sheet2!A:N,5,0) -> 16.12 | G205: =VLOOKUP(C205,Sheet2!A:N,6,0) -> 16.21 | H205: =VLOOKUP(C205,Sheet2!A:N,7,0) -> 0.56 | I205: =VLOOKUP(C205,Sheet2!A:N,8,0) -> 16.21 | J205: =VLOOKUP(C205,Sheet2!A:N,9,0) -> 16.53 | K205: =VLOOKUP(C205,Sheet2!A:N,10,0) -> 16.21 | L205: =VLOOKUP(C205,Sheet2!A:N,11,0) -> 7230980.5 | M205: =VLOOKUP(C205,Sheet2!A:N,12,0) -> 440567 | N205: =VLOOKUP(C205,Sheet2!A:N,13,0) -> 281 | O205: =VLOOKUP(C205,Sheet2!A:N,14,0) -> 11899
A206: 0 | B206: حق نهر الخير للتنمية | C206: =VLOOKUP(A206,Sheet1!C:F,2,0) -> #N/A | E206: =VLOOKUP(C206,Sheet2!A:N,4,0) -> #N/A | F206: =VLOOKUP(C206,Sheet2!A:N,5,0) -> #N/A | G206: =VLOOKUP(C206,Sheet2!A:N,6,0) -> #N/A | H206: =VLOOKUP(C206,Sheet2!A:N,7,0) -> #N/A | I206: =VLOOKUP(C206,Sheet2!A:N,8,0) -> #N/A | J206: =VLOOKUP(C206,Sheet2!A:N,9,0) -> #N/A | K206: =VLOOKUP(C206,Sheet2!A:N,10,0) -> #N/A | L206: =VLOOKUP(C206,Sheet2!A:N,11,0) -> #N/A | M206: =VLOOKUP(C206,Sheet2!A:N,12,0) -> #N/A | N206: =VLOOKUP(C206,Sheet2!A:N,13,0) -> #N/A | O206: =VLOOKUP(C206,Sheet2!A:N,14,0) -> #N/A
C207: =VLOOKUP(A207,Sheet1!C:F,2,0) -> #N/A | E207: =VLOOKUP(C207,Sheet2!A:N,4,0) -> #N/A | F207: =VLOOKUP(C207,Sheet2!A:N,5,0) -> #N/A | G207: =VLOOKUP(C207,Sheet2!A:N,6,0) -> #N/A | H207: =VLOOKUP(C207,Sheet2!A:N,7,0) -> #N/A | I207: =VLOOKUP(C207,Sheet2!A:N,8,0) -> #N/A | J207: =VLOOKUP(C207,Sheet2!A:N,9,0) -> #N/A | K207: =VLOOKUP(C207,Sheet2!A:N,10,0) -> #N/A | L207: =VLOOKUP(C207,Sheet2!A:N,11,0) -> #N/A | M207: =VLOOKUP(C207,Sheet2!A:N,12,0) -> #N/A | N207: =VLOOKUP(C207,Sheet2!A:N,13,0) -> #N/A | O207: =VLOOKUP(C207,Sheet2!A:N,14,0) -> #N/A
C208: =VLOOKUP(A208,Sheet1!C:F,2,0) -> #N/A | E208: =VLOOKUP(C208,Sheet2!A:N,4,0) -> #N/A | F208: =VLOOKUP(C208,Sheet2!A:N,5,0) -> #N/A | G208: =VLOOKUP(C208,Sheet2!A:N,6,0) -> #N/A | H208: =VLOOKUP(C208,Sheet2!A:N,7,0) -> #N/A | I208: =VLOOKUP(C208,Sheet2!A:N,8,0) -> #N/A | J208: =VLOOKUP(C208,Sheet2!A:N,9,0) -> #N/A | K208: =VLOOKUP(C208,Sheet2!A:N,10,0) -> #N/A | L208: =VLOOKUP(C208,Sheet2!A:N,11,0) -> #N/A | M208: =VLOOKUP(C208,Sheet2!A:N,12,0) -> #N/A | N208: =VLOOKUP(C208,Sheet2!A:N,13,0) -> #N/A | O208: =VLOOKUP(C208,Sheet2!A:N,14,0) -> #N/A
C209: =VLOOKUP(A209,Sheet1!C:F,2,0) -> #N/A | E209: =VLOOKUP(C209,Sheet2!A:N,4,0) -> #N/A | F209: =VLOOKUP(C209,Sheet2!A:N,5,0) -> #N/A | G209: =VLOOKUP(C209,Sheet2!A:N,6,0) -> #N/A | H209: =VLOOKUP(C209,Sheet2!A:N,7,0) -> #N/A | I209: =VLOOKUP(C209,Sheet2!A:N,8,0) -> #N/A | J209: =VLOOKUP(C209,Sheet2!A:N,9,0) -> #N/A | K209: =VLOOKUP(C209,Sheet2!A:N,10,0) -> #N/A | L209: =VLOOKUP(C209,Sheet2!A:N,11,0) -> #N/A | M209: =VLOOKUP(C209,Sheet2!A:N,12,0) -> #N/A | N209: =VLOOKUP(C209,Sheet2!A:N,13,0) -> #N/A | O209: =VLOOKUP(C209,Sheet2!A:N,14,0) -> #N/A
C210: =VLOOKUP(A210,Sheet1!C:F,2,0) -> #N/A | E210: =VLOOKUP(C210,Sheet2!A:N,4,0) -> #N/A | F210: =VLOOKUP(C210,Sheet2!A:N,5,0) -> #N/A | G210: =VLOOKUP(C210,Sheet2!A:N,6,0) -> #N/A | H210: =VLOOKUP(C210,Sheet2!A:N,7,0) -> #N/A | I210: =VLOOKUP(C210,Sheet2!A:N,8,0) -> #N/A | J210: =VLOOKUP(C210,Sheet2!A:N,9,0) -> #N/A | K210: =VLOOKUP(C210,Sheet2!A:N,10,0) -> #N/A | L210: =VLOOKUP(C210,Sheet2!A:N,11,0) -> #N/A | M210: =VLOOKUP(C210,Sheet2!A:N,12,0) -> #N/A | N210: =VLOOKUP(C210,Sheet2!A:N,13,0) -> #N/A | O210: =VLOOKUP(C210,Sheet2!A:N,14,0) -> #N/A
C211: =VLOOKUP(A211,Sheet1!C:F,2,0) -> #N/A | E211: =VLOOKUP(C211,Sheet2!A:N,4,0) -> #N/A | F211: =VLOOKUP(C211,Sheet2!A:N,5,0) -> #N/A | G211: =VLOOKUP(C211,Sheet2!A:N,6,0) -> #N/A | H211: =VLOOKUP(C211,Sheet2!A:N,7,0) -> #N/A | I211: =VLOOKUP(C211,Sheet2!A:N,8,0) -> #N/A | J211: =VLOOKUP(C211,Sheet2!A:N,9,0) -> #N/A | K211: =VLOOKUP(C211,Sheet2!A:N,10,0) -> #N/A | L211: =VLOOKUP(C211,Sheet2!A:N,11,0) -> #N/A | M211: =VLOOKUP(C211,Sheet2!A:N,12,0) -> #N/A | N211: =VLOOKUP(C211,Sheet2!A:N,13,0) -> #N/A | O211: =VLOOKUP(C211,Sheet2!A:N,14,0) -> #N/A
C212: =VLOOKUP(A212,Sheet1!C:F,2,0) -> #N/A | E212: =VLOOKUP(C212,Sheet2!A:N,4,0) -> #N/A | F212: =VLOOKUP(C212,Sheet2!A:N,5,0) -> #N/A | G212: =VLOOKUP(C212,Sheet2!A:N,6,0) -> #N/A | H212: =VLOOKUP(C212,Sheet2!A:N,7,0) -> #N/A | I212: =VLOOKUP(C212,Sheet2!A:N,8,0) -> #N/A | J212: =VLOOKUP(C212,Sheet2!A:N,9,0) -> #N/A | K212: =VLOOKUP(C212,Sheet2!A:N,10,0) -> #N/A | L212: =VLOOKUP(C212,Sheet2!A:N,11,0) -> #N/A | M212: =VLOOKUP(C212,Sheet2!A:N,12,0) -> #N/A | N212: =VLOOKUP(C212,Sheet2!A:N,13,0) -> #N/A | O212: =VLOOKUP(C212,Sheet2!A:N,14,0) -> #N/A
C213: =VLOOKUP(A213,Sheet1!C:F,2,0) -> #N/A | E213: =VLOOKUP(C213,Sheet2!A:N,4,0) -> #N/A | F213: =VLOOKUP(C213,Sheet2!A:N,5,0) -> #N/A | G213: =VLOOKUP(C213,Sheet2!A:N,6,0) -> #N/A | H213: =VLOOKUP(C213,Sheet2!A:N,7,0) -> #N/A | I213: =VLOOKUP(C213,Sheet2!A:N,8,0) -> #N/A | J213: =VLOOKUP(C213,Sheet2!A:N,9,0) -> #N/A | K213: =VLOOKUP(C213,Sheet2!A:N,10,0) -> #N/A | L213: =VLOOKUP(C213,Sheet2!A:N,11,0) -> #N/A | M213: =VLOOKUP(C213,Sheet2!A:N,12,0) -> #N/A | N213: =VLOOKUP(C213,Sheet2!A:N,13,0) -> #N/A | O213: =VLOOKUP(C213,Sheet2!A:N,14,0) -> #N/A
C214: =VLOOKUP(A214,Sheet1!C:F,2,0) -> #N/A | E214: =VLOOKUP(C214,Sheet2!A:N,4,0) -> #N/A | F214: =VLOOKUP(C214,Sheet2!A:N,5,0) -> #N/A | G214: =VLOOKUP(C214,Sheet2!A:N,6,0) -> #N/A | H214: =VLOOKUP(C214,Sheet2!A:N,7,0) -> #N/A | I214: =VLOOKUP(C214,Sheet2!A:N,8,0) -> #N/A | J214: =VLOOKUP(C214,Sheet2!A:N,9,0) -> #N/A | K214: =VLOOKUP(C214,Sheet2!A:N,10,0) -> #N/A | L214: =VLOOKUP(C214,Sheet2!A:N,11,0) -> #N/A | M214: =VLOOKUP(C214,Sheet2!A:N,12,0) -> #N/A | N214: =VLOOKUP(C214,Sheet2!A:N,13,0) -> #N/A | O214: =VLOOKUP(C214,Sheet2!A:N,14,0) -> #N/A
C215: =VLOOKUP(A215,Sheet1!C:F,2,0) -> #N/A | E215: =VLOOKUP(C215,Sheet2!A:N,4,0) -> #N/A | F215: =VLOOKUP(C215,Sheet2!A:N,5,0) -> #N/A | G215: =VLOOKUP(C215,Sheet2!A:N,6,0) -> #N/A | H215: =VLOOKUP(C215,Sheet2!A:N,7,0) -> #N/A | I215: =VLOOKUP(C215,Sheet2!A:N,8,0) -> #N/A | J215: =VLOOKUP(C215,Sheet2!A:N,9,0) -> #N/A | K215: =VLOOKUP(C215,Sheet2!A:N,10,0) -> #N/A | L215: =VLOOKUP(C215,Sheet2!A:N,11,0) -> #N/A | M215: =VLOOKUP(C215,Sheet2!A:N,12,0) -> #N/A | N215: =VLOOKUP(C215,Sheet2!A:N,13,0) -> #N/A | O215: =VLOOKUP(C215,Sheet2!A:N,14,0) -> #N/A
C216: =VLOOKUP(A216,Sheet1!C:F,2,0) -> #N/A | E216: =VLOOKUP(C216,Sheet2!A:N,4,0) -> #N/A | F216: =VLOOKUP(C216,Sheet2!A:N,5,0) -> #N/A | G216: =VLOOKUP(C216,Sheet2!A:N,6,0) -> #N/A | H216: =VLOOKUP(C216,Sheet2!A:N,7,0) -> #N/A | I216: =VLOOKUP(C216,Sheet2!A:N,8,0) -> #N/A | J216: =VLOOKUP(C216,Sheet2!A:N,9,0) -> #N/A | K216: =VLOOKUP(C216,Sheet2!A:N,10,0) -> #N/A | L216: =VLOOKUP(C216,Sheet2!A:N,11,0) -> #N/A | M216: =VLOOKUP(C216,Sheet2!A:N,12,0) -> #N/A | N216: =VLOOKUP(C216,Sheet2!A:N,13,0) -> #N/A | O216: =VLOOKUP(C216,Sheet2!A:N,14,0) -> #N/A
C217: =VLOOKUP(A217,Sheet1!C:F,2,0) -> #N/A | E217: =VLOOKUP(C217,Sheet2!A:N,4,0) -> #N/A | F217: =VLOOKUP(C217,Sheet2!A:N,5,0) -> #N/A | G217: =VLOOKUP(C217,Sheet2!A:N,6,0) -> #N/A | H217: =VLOOKUP(C217,Sheet2!A:N,7,0) -> #N/A | I217: =VLOOKUP(C217,Sheet2!A:N,8,0) -> #N/A | J217: =VLOOKUP(C217,Sheet2!A:N,9,0) -> #N/A | K217: =VLOOKUP(C217,Sheet2!A:N,10,0) -> #N/A | L217: =VLOOKUP(C217,Sheet2!A:N,11,0) -> #N/A | M217: =VLOOKUP(C217,Sheet2!A:N,12,0) -> #N/A | N217: =VLOOKUP(C217,Sheet2!A:N,13,0) -> #N/A | O217: =VLOOKUP(C217,Sheet2!A:N,14,0) -> #N/A
...

Sheet Sheet4
C2: كود ISIN | E2: القطاع
C3: (مجموعة عامر القابضة (عامر جروب | D3: تفاصيل إضافية للشركة | E3: EGS675S1C011 | F3: عقارات
C4: A.T.LEASEالتوفيق للتأجير التمويلي -أية.تي.ليس | D4: تفاصيل إضافية للشركة | E4: EGS676N1C015 | F4: خدمات مالية غير مصرفية
C5: EAC المصرية العربية (ثمار) لتداول الاوراق المالية والسندات | D5: تفاصيل إضافية للشركة | E5: EGS681D1C010 | F5: خدمات مالية غير مصرفية
C6: EGX 30 INDEX ETF-وثائق استثمار شركة صناديق المؤشرات | D6: تفاصيل إضافية للشركة | E6: EGS69491M015 | F6: خدمات مالية غير مصرفية
C7: Taaleem Management Services تعليم لخدمات الإدارة | D7: تفاصيل إضافية للشركة | E7: EGS597R1C017 | F7: خدمات تعليمية
C8: أم بي للهندسةM.B | D8: تفاصيل إضافية للشركة | E8: EGS221V1C015 | F8: خدمات و منتجات صناعية وسيارات
C9: إعمار مصر للتنمية | D9: تفاصيل إضافية للشركة | E9: EGS673Y1C015 | F9: عقارات
C10: ابن سينا فارما | D10: تفاصيل إضافية للشركة | E10: EGS512O1C012 | F10: رعاية صحية و ادوية
C11: ابوقير للاسمدة والصناعات الكيماوية | D11: تفاصيل إضافية للشركة | E11: EGS38191C010 | F11: موارد أساسية
C12: اجواء للصناعات الغذائية - مصر | D12: تفاصيل إضافية للشركة | E12: EGS30211C014 | F12: أغذية و مشروبات و تبغ
C13: ارابيا انفستمنتس هولدنج | D13: تفاصيل إضافية للشركة | E13: EGS21351C019 | F13: خدمات مالية غير مصرفية
C14: ارابيا للاستثمار والتنمية | D14: تفاصيل إضافية للشركة | E14: EGS65R01C015 | F14: خدمات مالية غير مصرفية
... C241: يونيفرسال لصناعة مواد التعبئة و التغليف و الورق - يونيباك | D241: تفاصيل إضافية للشركة | E241: EGS38161C013 | F241: ورق ومواد تعبئة و تغليف

Sheet Sheet2
A1: =B2 -> اسم الشركة | B1: اسم الشركة | C1: القطاع | D1: الإقفال السابق | E1: سعر الفتح | F1: سعر الاغلاق | G1: نسبة التغير% | H1: آخر سعر | I1: اعلى سعر | J1: اقل سعر | K1: القيمة (جنيه) | L1: الكمية | M1: عدد العمليات | N1: رأس المال السوقى (مليون جنيه)
A2: =B3 -> جنيه مصري | B2: اسم الشركة | C2: القطاع | D2: الإقفال السابق | E2: سعر الفتح | F2: سعر الاغلاق | G2: نسبة التغير% | H2: آخر سعر | I2: اعلى سعر | J2: اقل سعر | K2: القيمة (جنيه) | L2: الكمية | M2: عدد العمليات | N2: رأس المال السوقى (مليون جنيه)
A3: =B4 -> تفاصيل إضافية للشركة | B3: جنيه مصري
A4: =B5 -> صكوك بكرة للتصكيك الاصدار الاول ابريل 2032 ع.م | B4: تفاصيل إضافية للشركة | D4: 106.13 | E4: 106.13 | F4: 105.97 | G4: -0.15 | H4: 105.97 | I4: 105.97 | J4: 105.97 | K4: 14835.8 | L4: 140 | M4: 1 | N4: 3179
A5: =B6 -> تفاصيل إضافية للشركة | B5: صكوك بكرة للتصكيك الاصدار الاول ابريل 2032 ع.م
A6: =B7 -> فيركيم مصر للاسمدة والكيماويات | B6: تفاصيل إضافية للشركة | C6: موارد أساسية | D6: 76 | E6: 76 | F6: 75.38 | G6: -0.82 | H6: 75.38 | I6: 76.59 | J6: 75.34 | K6: 4375087.7 | L6: 57890 | M6: 196 | N6: 30152
A7: =B8 -> تفاصيل إضافية للشركة | B7: فيركيم مصر للاسمدة والكيماويات
A8: =B9 -> يو للتمويل الاستهلاكى | B8: تفاصيل إضافية للشركة | C8: خدمات مالية غير مصرفية | D8: 11.64 | E8: 11.64 | F8: 11.92 | G8: 2.41 | H8: 11.92 | I8: 12 | J8: 11.58 | K8: 88472463 | L8: 7402221 | M8: 1188 | N8: 25108
A9: =B10 -> تفاصيل إضافية للشركة | B9: يو للتمويل الاستهلاكى
A10: =B11 -> جو جرين للاستثمار الزراعى والتنمية | B10: تفاصيل إضافية للشركة | C10: أغذية و مشروبات و تبغ | D10: 1.49 | E10: 1.49 | F10: 1.49 | G10: 0 | H10: 1.49 | I10: 1.52 | J10: 1.48 | K10: 21330843 | L10: 14288808 | M10: 789 | N10: 2086
A11: =B12 -> تفاصيل إضافية للشركة | B11: جو جرين للاستثمار الزراعى والتنمية
A12: =B13 -> بنيان للتنمية والتجارة | B12: تفاصيل إضافية للشركة | C12: عقارات | D12: 5.26 | E12: 5.26 | F12: 5.35 | G12: 1.71 | H12: 5.35 | I12: 5.48 | J12: 5.15 | K12: 1.591459e+08 | L12: 30328220 | M12: 1833 | N12: 9119
A13: =B14 -> تفاصيل إضافية للشركة | B13: بنيان للتنمية والتجارة
A14: =B15 -> قرة لمشروعات الطاقة والاستثمار | B14: تفاصيل إضافية للشركة | C14: مقاولات و إنشاءات هندسية | D14: 3.49 | E14: 3.49 | F14: 3.36 | G14: -3.72 | H14: 3.36 | I14: 3.53 | J14: 3.36 | K14: 3.3522354e+08 | L14: 98105048 | M14: 5252 | N14: 7560
A15: =B16 -> تفاصيل إضافية للشركة | B15: قرة لمشروعات الطاقة والاستثمار
A16: =B17 -> الدولية للأسمدة والكيماويات | B16: تفاصيل إضافية للشركة | C16: تجارة و موزعون | D16: 15.05 | E16: 15.05 | F16: 15.14 | G16: 0.6 | H16: 15.14 | I16: 15.21 | J16: 15.01 | K16: 2813156.8 | L16: 186499 | M16: 180 | N16: 1768
A17: =B18 -> تفاصيل إضافية للشركة | B17: الدولية للأسمدة والكيماويات
A18: =B19 -> جورميه ايجيبت دوت كوم للاغذية | B18: تفاصيل إضافية للشركة | C18: تجارة و موزعون | D18: 12.79 | E18: 12.79 | F18: 12.7 | G18: -0.7 | H18: 12.7 | I18: 12.88 | J18: 12.6 | K18: 28203630 | L18: 2230803 | M18: 529 | N18: 5080
A19: =B20 -> تفاصيل إضافية للشركة | B19: جورميه ايجيبت دوت كوم للاغذية
A20: =B21 -> حق اكتتاب شركة اسباير كابيتال القابضة للاستثمارات المالية-3 | B20: تفاصيل إضافية للشركة | C20: خدمات مالية غير مصرفية | D20: 0.098 | E20: 0.098 | F20: 0.088 | G20: -10.2 | H20: 0.088 | I20: 0.099 | J20: 0.087 | K20: 7165583 | L20: 79721296 | M20: 756 | N20: 167
A21: =B22 -> تفاصيل إضافية للشركة | B21: حق اكتتاب شركة اسباير كابيتال القابضة للاستثمارات المالية-3
A22: =B23 -> توسع للتخصيم | B22: تفاصيل إضافية للشركة | C22: خدمات مالية غير مصرفية | D22: 5.55 | E22: 5.55 | F22: 5.42 | G22: -2.34 | H22: 5.41 | I22: 5.57 | J22: 5.23 | K22: 2236864.5 | L22: 410915 | M22: 225 | N22: 623
A23: =B24 -> تفاصيل إضافية للشركة | B23: توسع للتخصيم
A24: =B25 -> اية كابيتال القابضة | B24: تفاصيل إضافية للشركة | C24: عقارات | D24: 9.2 | E24: 9.2 | F24: 9.06 | G24: -1.52 | H24: 9.06 | I24: 9.39 | J24: 9.02 | K24: 5567868.9 | L24: 605796 | M24: 447 | N24: 6625
A25: =B26 -> تفاصيل إضافية للشركة | B25: اية كابيتال القابضة
A26: =B27 -> الوطنية للطباعة | B26: تفاصيل إضافية للشركة | C26: ورق ومواد تعبئة و تغليف | D26: 25.02 | E26: 25.02 | F26: 25.87 | G26: 3.4 | H26: 25.9 | I26: 26 | J26: 25.1 | K26: 559078.21 | L26: 21620 | M26: 30 | N26: 5571
A27: =B28 -> تفاصيل إضافية للشركة | B27: الوطنية للطباعة
A28: =B29 -> اكت فاينانشال للاستشارات | B28: تفاصيل إضافية للشركة | C28: خدمات مالية غير مصرفية | D28: 2.71 | E28: 2.71 | F28: 2.72 | G28: 0.37 | H28: 2.72 | I28: 2.74 | J28: 2.71 | K28: 5141239 | L28: 1887396 | M28: 222 | N28: 3108
A29: =B30 -> تفاصيل إضافية للشركة | B29: اكت فاينانشال للاستشارات
A30: =B31 -> ديجيتايز للاستثمار والتقنية | B30: تفاصيل إضافية للشركة | C30: اتصالات و اعلام و تكنولوجيا المعلومات | D30: 2.62 | E30: 2.62 | F30: 2.62 | G30: 0 | H30: 2.63 | I30: 2.66 | J30: 2.61 | K30: 1194471.1 | L30: 454252 | M30: 151 | N30: 283
A31: =B32 -> تفاصيل إضافية للشركة | B31: ديجيتايز للاستثمار والتقنية
A32: =B33 -> أم بي للهندسةM.B | B32: تفاصيل إضافية للشركة | C32: خدمات و منتجات صناعية وسيارات | D32: 3.73 | E32: 3.73 | F32: 3.67 | G32: -1.61 | H32: 3.67 | I32: 3.75 | J32: 3.66 | K32: 1639457.8 | L32: 443936 | M32: 134 | N32: 743
A33: =B34 -> تفاصيل إضافية للشركة | B33: أم بي للهندسةM.B
A34: =B35 -> سبأ الدولية للأدوية والصناعات الكيماوية | B34: تفاصيل إضافية للشركة | C34: رعاية صحية و ادوية | D34: 3.47 | E34: 3.47 | F34: 3.46 | G34: -0.29 | H34: 3.46 | I34: 3.49 | J34: 3.43 | K34: 15147809 | L34: 4381732 | M34: 381 | N34: 865
A35: =B36 -> تفاصيل إضافية للشركة | B35: سبأ الدولية للأدوية والصناعات الكيماوية
A36: =B37 -> لوتس للتنمية والاستثمار الزراعى | B36: تفاصيل إضافية للشركة | C36: أغذية و مشروبات و تبغ | D36: 0.752 | E36: 0.752 | F36: 0.737 | G36: -1.99 | H36: 0.737 | I36: 0.771 | J36: 0.732 | K36: 52499263 | L36: 70138166 | M36: 1698 | N36: 774
A37: =B38 -> تفاصيل إضافية للشركة | B37: لوتس للتنمية والاستثمار الزراعى
A38: =B39 -> المصرف المتحد | B38: تفاصيل إضافية للشركة | C38: بنوك | D38: 13.92 | E38: 13.92 | F38: 13.93 | G38: 0.07 | H38: 13.93 | I38: 14.1 | J38: 13.92 | K38: 4345580.9 | L38: 310858 | M38: 199 | N38: 15323
A39: =B40 -> تفاصيل إضافية للشركة | B39: المصرف المتحد
A40: =B41 -> ارابيا للاستثمار والتنمية | B40: تفاصيل إضافية للشركة | C40: خدمات مالية غير مصرفية | D40: 0.677 | E40: 0.677 | F40: 0.66 | G40: -2.51 | H40: 0.66 | I40: 0.686 | J40: 0.654 | K40: 8992505.3 | L40: 13410501 | M40: 339 | N40: 1028
...

Sheet Sheet6
C2: اسم الشركة | D2: الإقفال السابق | E2: سعر الإغلاق | F2: نسبة التغير% | G2: القيمة (جنيه) | H2: الكمية | I2: عدد العمليات | J2: رأس المال السوقى (مليون جنيه)
C3: اسم الشركة | D3: الإقفال السابق | E3: سعر الإغلاق | F3: نسبة التغير% | G3: القيمة (جنيه) | H3: الكمية | I3: عدد العمليات | J3: رأس المال السوقى (مليون جنيه)
C4: بي اي دي- البدر للاستثمار والتنمية | D4: 1.35 | E4: 1.41 | F4: 4.44 | G4: 444633.41 | H4: 316432 | I4: 59 | J4: 32
C5: ركاز القابضة للاستثمارات المالية | D5: 4.51 | E5: 4.39 | F5: -2.66 | G5: 919510.59 | H5: 211057 | I5: 125 | J5: 88
C6: انترناشيونال بزنيس كوربوريشن للتجارة والتوكيلات التجارية | D6: 11.97 | E6: 12 | F6: 0.25 | G6: 931708.23 | H6: 77877 | I6: 100 | J6: 292
C7: المصرية الكويتية للأستثمار والتجارة | D7: 2.84 | E7: 2.84 | F7: 0 | G7: 101452.21 | H7: 36255 | I7: 43 | J7: 57
C8: بى اى جى للتجارة والاستثمار | D8: 0.188 | E8: 0.187 | F8: -0.53 | G8: 621126.33 | H8: 3327164 | I8: 118 | J8: 61
C9: يوتوبيا للاستثمار العقارى والسياحى | D9: 80.44 | E9: 80.18 | F9: -0.32 | G9: 468058.33 | H9: 5805 | I9: 76 | J9: 241
C10: نوفيدا للإستثمار والتكنولوجيا | D10: 2.63 | E10: 2.59 | F10: -1.52 | G10: 1284321.6 | H10: 491606 | I10: 98 | J10: 78
C11: فيوتشر كير للصناعات الطبية | D11: 7.9 | E11: 7.13 | F11: -9.75 | G11: 57101913 | H11: 7932913 | I11: 3480 | J11: 411
C12: الفنار للمقاولات العمومية والإنشاءات والتجارة والاستيراد | D12: 9.85 | E12: 10.83 | F12: 9.95 | G12: 8179286.3 | H12: 772469 | I12: 367 | J12: 173
C13: الاولي للاستثمار والتنمية العقارية | D13: 4.71 | E13: 4.7 | F13: -0.21 | G13: 2345247.4 | H13: 483571 | I13: 172 | J13: 65
C14: المجموعة المتكاملة للأعمال الهندسية | D14: 0.421 | E14: 0.433 | F14: 2.85 | G14: 8216814.3 | H14: 19077129 | I14: 413 | J14: 217
C15: فرتيكا للصناعة و التجارة | D15: 7.16 | E15: 7.1 | F15: -0.84 | G15: 493956.59 | H15: 69398 | I15: 126 | J15: 182
... C19: هيبكو للاستثمارات التجارية والتنمية العقارية | D19: 10 | E19: 11 | F19: 10 | G19: 24273649 | H19: 2234758 | I19: 1146 | J19: 440

Sheet Sheet5
D1: اسم الورقة المالية | E1: الرمز | F1: الكود الدولي | G1: رابط الاخبار | H1: رابط الاخبار
D2: مرسيليا المصرية الخليجية للاستثمار العقارى | E2: MAAL | F2: EGS739Z1C016 | G2: https://www.egx.com.eg/ar/NewsList.aspx?ISIN=EGS739Z1C016 | H2: =HYPERLINK(G2) -> https://www.egx.com.eg/ar/NewsList.aspx?ISIN=EGS739Z1C016
D3: المصرية لنظم التعليم الحديثة | E3: MOED | F3: EGS729F1C012 | G3: https://www.egx.com.eg/ar/NewsList.aspx?ISIN=EGS729F1C012 | H3: =HYPERLINK(G3) -> https://www.egx.com.eg/ar/NewsList.aspx?ISIN=EGS729F1C012
D4: الجيزةالعامة للمقاولات والاستثمارالعقارى | E4: GGCC | F4: EGS21541C015 | G4: https://www.egx.com.eg/ar/NewsList.aspx?ISIN=EGS21541C015 | H4: =HYPERLINK(G4) -> https://www.egx.com.eg/ar/NewsList.aspx?ISIN=EGS21541C015
D5: مصر لصناعة الكيماويات | E5: MICH | F5: EGS38211C016 | G5: https://www.egx.com.eg/ar/NewsList.aspx?ISIN=EGS38211C016 | H5: =HYPERLINK(G5) -> https://www.egx.com.eg/ar/NewsList.aspx?ISIN=EGS38211C016
D6: التعمير والاستشارات الهندسية | E6: DAPH | F6: EGS65081C019 | G6: https://www.egx.com.eg/ar/NewsList.aspx?ISIN=EGS65081C019 | H6: =HYPERLINK(G6) -> https://www.egx.com.eg/ar/NewsList.aspx?ISIN=EGS65081C019
D7: القناة للتوكيلات الملاحية | E7: CSAG | F7: EGS44031C010 | G7: https://www.egx.com.eg/ar/NewsList.aspx?ISIN=EGS44031C010 | H7: =HYPERLINK(G7) -> https://www.egx.com.eg/ar/NewsList.aspx?ISIN=EGS44031C010
D8: جهينة للصناعات الغذائية | E8: JUFO | F8: EGS30901C010 | G8: https://www.egx.com.eg/ar/NewsList.aspx?ISIN=EGS30901C010 | H8: =HYPERLINK(G8) -> https://www.egx.com.eg/ar/NewsList.aspx?ISIN=EGS30901C010
D9: بنك فيصل الاسلامي المصرية بالجنية | E9: FAIT | F9: EGS60321C014 | G9: https://www.egx.com.eg/ar/NewsList.aspx?ISIN=EGS60321C014 | H9: =HYPERLINK(G9) -> https://www.egx.com.eg/ar/NewsList.aspx?ISIN=EGS60321C014
D10: المصرية للأقمار الصناعية (نايل سات) | E10: EGSA | F10: EGS48022C015 | G10: https://www.egx.com.eg/ar/NewsList.aspx?ISIN=EGS48022C015 | H10: =HYPERLINK(G10) -> https://www.egx.com.eg/ar/NewsList.aspx?ISIN=EGS48022C015
D11: جيتكس للاستثمارات التجارية والصناعية | E11: GTEX | F11: EGS59U92C011 | G11: https://www.egx.com.eg/ar/NewsList.aspx?ISIN=EGS59U92C011 | H11: =HYPERLINK(G11) -> https://www.egx.com.eg/ar/NewsList.aspx?ISIN=EGS59U92C011
D12: حق اكتتاب شركة التوفيق للتأجير التمويلى - ايه.تى.ليس 3 | E12: ATLC_r3 | F12: EGS923X1C014 | G12: https://www.egx.com.eg/ar/NewsList.aspx?ISIN=EGS923X1C014 | H12: =HYPERLINK(G12) -> https://www.egx.com.eg/ar/NewsList.aspx?ISIN=EGS923X1C014
D13: لوتس للتنمية والاستثمار الزراعى | E13: LUTS | F13: EGS07661C019 | G13: https://www.egx.com.eg/ar/NewsList.aspx?ISIN=EGS07661C019 | H13: =HYPERLINK(G13) -> https://www.egx.com.eg/ar/NewsList.aspx?ISIN=EGS07661C019
... D237: جدوى للتنمية الصناعية | E237: GDWA | F237: EGS3JM11C012 | G237: https://www.egx.com.eg/ar/NewsList.aspx?ISIN=EGS3JM11C012 | H237: =HYPERLINK(G237) -> https://www.egx.com.eg/ar/NewsList.aspx?ISIN=EGS3JM11C012
G238: https://www.egx.com.eg/ar/NewsList.aspx?ISIN= | H238: =HYPERLINK(G238) -> https://www.egx.com.eg/ar/NewsList.aspx?ISIN=

Sheet Sheet1
C1: الرمز | D1: اسم الشركة1 | E1: اسم الشركة2 | F1: الرمز
C2: MAAL | D2: مرسيليا المصرية الخليجية للاستثمار العقارى | E2: #N/A | F2: MAAL | H2: (مجموعة عامر القابضة (عامر جروب | J2: EGS675S1C011 | K2: عقارات
C3: MOED | D3: المصرية لنظم التعليم الحديثة | E3: #N/A | F3: MOED | H3: A.T.LEASEالتوفيق للتأجير التمويلي -أية.تي.ليس | J3: EGS676N1C015 | K3: خدمات مالية غير مصرفية | L3: عقارات
C4: GGCC | D4: الجيزةالعامة للمقاولات والاستثمارالعقارى | E4: #N/A | F4: GGCC | H4: EAC المصرية العربية (ثمار) لتداول الاوراق المالية والسندات | J4: EGS681D1C010 | K4: خدمات مالية غير مصرفية | L4: خدمات مالية غير مصرفية
C5: MICH | D5: مصر لصناعة الكيماويات | E5: مصر لصناعة الكيماويات | F5: MICH | H5: EGX 30 INDEX ETF-وثائق استثمار شركة صناديق المؤشرات | J5: EGS69491M015 | K5: خدمات مالية غير مصرفية | L5: خدمات مالية غير مصرفية
C6: DAPH | D6: التعمير والاستشارات الهندسية | E6: #N/A | F6: DAPH | H6: Taaleem Management Services تعليم لخدمات الإدارة | J6: EGS597R1C017 | K6: خدمات تعليمية | L6: خدمات مالية غير مصرفية
C7: CSAG | D7: القناة للتوكيلات الملاحية | E7: القناة للتوكيلات | F7: CSAG | H7: أم بي للهندسةM.B | J7: EGS221V1C015 | K7: خدمات و منتجات صناعية وسيارات | L7: خدمات تعليمية
C8: JUFO | D8: جهينة للصناعات الغذائية | E8: جهينة الغذائية | F8: JUFO | H8: إعمار مصر للتنمية | J8: EGS673Y1C015 | K8: عقارات | L8: خدمات و منتجات صناعية وسيارات
C9: FAIT | D9: بنك فيصل الاسلامي المصرية بالجنية | E9: #N/A | F9: FAIT | H9: ابن سينا فارما | J9: EGS512O1C012 | K9: رعاية صحية و ادوية | L9: عقارات
C10: EGSA | D10: المصرية للأقمار الصناعية (نايل سات) | E10: نايل سات | F10: EGSA | H10: ابوقير للاسمدة والصناعات الكيماوية | J10: EGS38191C010 | K10: موارد أساسية | L10: رعاية صحية و ادوية
C11: GTEX | D11: جيتكس للاستثمارات التجارية والصناعية | E11: #N/A | F11: GTEX | H11: اجواء للصناعات الغذائية - مصر | J11: EGS30211C014 | K11: أغذية و مشروبات و تبغ | L11: موارد أساسية
C12: LUTS | D12: لوتس للتنمية والاستثمار الزراعى | E12: #N/A | F12: LUTS | H12: ارابيا انفستمنتس هولدنج | J12: EGS21351C019 | K12: خدمات مالية غير مصرفية | L12: أغذية و مشروبات و تبغ
C13: VALU | D13: يو للتمويل الاستهلاكى | E13: ڤاليو | F13: VALU | H13: ارابيا للاستثمار والتنمية | J13: EGS65R01C015 | K13: خدمات مالية غير مصرفية | L13: خدمات مالية غير مصرفية
C14: BONY | D14: بنيان للتنمية والتجارة | E14: بونى | F14: BONY | H14: اسباير كابيتال القابضة للاستثمارات المالية | J14: EGS691L1C018 | K14: خدمات مالية غير مصرفية | L14: خدمات مالية غير مصرفية
C15: WKOL | D15: وادي كوم امبو لاستصلاح الاراضي | E15: #N/A | F15: WKOL | H15: اسمنت سيناء | J15: EGS3C401C014 | K15: مواد البناء | L15: خدمات مالية غير مصرفية
C16: AIH | D16: ارابيا انفستمنتس هولدنج | E16: #N/A | F16: AIH | H16: اسيك للتعدين - اسكوم | J16: EGS10001C013 | K16: موارد أساسية | L16: مواد البناء
C17: IFAP | D17: الدوليه للمحاصيل الزراعيه | E17: الدولية للمحاصيل | F17: IFAP | H17: اصول E.S.B. للوساطة في الاوراق المالية | J17: EGS68181C014 | K17: خدمات مالية غير مصرفية | L17: موارد أساسية
C18: APSW | D18: العربيه وبولفارا للغزل والنسيج - يونيراب | E18: #N/A | F18: APSW | H18: اطلس للاستثمار والصناعات الغذائية | J18: EGS071L1C018 | K18: عقارات | L18: خدمات مالية غير مصرفية
C19: UEGC | D19: الصعيد العامة للمقاولات والاستثمار العقاري SCCD | E19: #N/A | F19: UEGC | H19: اكت فاينانشال للاستشارات | J19: EGS7D5P1C019 | K19: خدمات مالية غير مصرفية | L19: عقارات
C20: CANA | D20: بنك قناة السويس شركة مساهمة مصرية | E20: بنك قناة السويس | F20: CANA | H20: اكتوبر فارما | J20: EGS380R1C018 | K20: رعاية صحية و ادوية | L20: خدمات مالية غير مصرفية
C21: ATQA | D21: مصر الوطنية للصلب - عتاقة | E21: عتاقة | F21: ATQA | H21: الاستثمار العقاري العربي - اليكو | J21: EGS65011C016 | K21: عقارات | L21: رعاية صحية و ادوية
C22: NAHO | D22: النعيم القابضة للاستثمارات | E22: #N/A | F22: NAHO | H22: الاسكندرية لتداول الحاويات والبضائع | J22: EGS42111C012 | K22: خدمات النقل والشحن | L22: عقارات
C23: PHDC | D23: بالم هيلز للتعمير | E23: بالم هيلز | F23: PHDC | H23: الاسكندرية للادوية والصناعات الكيماوية | J23: EGS38341C011 | K23: رعاية صحية و ادوية | L23: خدمات النقل والشحن
C24: ASCM | D24: اسيك للتعدين - اسكوم | E24: #N/A | F24: ASCM | H24: الاسكندرية للخدمات الطبية - المركز الطبى الجديد - الاسكندرية | J24: EGS72081C010 | K24: رعاية صحية و ادوية | L24: رعاية صحية و ادوية
C25: SCTS | D25: قناة السويس لتوطين التكنولوجيا | E25: قناة السويس لتوطين التكنولوجيا | F25: SCTS | H25: الاسكندرية للزيوت المعدنية | J25: EGS380P1C010 | K25: طاقة وخدمات مساندة | L25: رعاية صحية و ادوية
C26: SWDY | D26: السويدى اليكتريك | E26: السويدي | F26: SWDY | H26: الاسكندرية للغزل والنسيج (سبينالكس) | J26: EGS32041C013 | K26: منسوجات و سلع معمرة | L26: طاقة وخدمات مساندة
C27: EAST | D27: الشرقية - ايسترن كومباني | E27: ايسترن كومباني | F27: EAST | H27: الاسكندريه الوطنيه للاستثمارات الماليه | J27: EGS67331C016 | K27: خدمات مالية غير مصرفية | L27: منسوجات و سلع معمرة
C28: ABUK | D28: ابوقير للاسمدة والصناعات الكيماوية | E28: أبو قير للأسمدة | F28: ABUK | H28: الاسماعيلية الجديدة للتطوير والتنمية العمرانية-شركة منقسمة | J28: EGS214Q1C011 | K28: عقارات | L28: خدمات مالية غير مصرفية
C29: ZEOT | D29: الزيوت المستخلصة ومنتجاتها | E29: #N/A | F29: ZEOT | H29: الاسماعيلية الوطنية للصناعات الغذائية (فوديكو) | J29: EGS01041C010 | K29: أغذية و مشروبات و تبغ | L29: عقارات
C30: MPCI | D30: ممفيس للادوية والصناعات الكيماوية | E30: #N/A | F30: MPCI | H30: الاسماعيلية مصر للدواجن | J30: EGS02021C011 | K30: أغذية و مشروبات و تبغ | L30: أغذية و مشروبات و تبغ
C31: EASB | D31: EAC المصرية العربية (ثمار) لتداول الاوراق المالية والسندات | E31: #N/A | F31: EASB | H31: الالومنيوم العربية | J31: EGS3D031C018 | K31: موارد أساسية | L31: أغذية و مشروبات و تبغ
C32: CICH | D32: سى اى كابيتال القابضة للاستثمارات المالية | E32: سي آي كابيتال | F32: CICH | H32: الاهرام للطباعة و التغليف | J32: EGS360A1C011 | K32: ورق ومواد تعبئة و تغليف | L32: موارد أساسية
C33: BTFH | D33: بلتون القابضة | E33: بلتون المالية القابضة | F33: BTFH | H33: الاهلي للتنمية والاستثمار | J33: EGS69021C011 | K33: خدمات مالية غير مصرفية | L33: ورق ومواد تعبئة و تغليف
C34: EOSB | D34: العروبة للسمسرة فى الأوراق المالية | E34: #N/A | F34: EOSB | H34: البنك التجاري الدولي -مصر (سى اى بى ) | J34: EGS60121C018 | K34: بنوك | L34: خدمات مالية غير مصرفية
C35: DSCW | D35: دايس للملابس الجاهزة | E35: دايس | F35: DSCW | H35: البنك المصري الخليجي | J35: EGS60182C010 | K35: بنوك | L35: بنوك
C36: OCPH | D36: اكتوبر فارما | E36: #N/A | F36: OCPH | H36: البنك المصري لتنمية الصادرات | J36: EGS60241C014 | K36: بنوك | L36: بنوك
C37: EDFM | D37: مطاحن شرق الدلتا | E37: #N/A | F37: EDFM | H37: التعمير والاستشارات الهندسية | J37: EGS65081C019 | K37: عقارات | L37: بنوك
C38: GSSC | D38: العامة للصوامع والتخزين | E38: العامة للصوامع | F38: GSSC | H38: الجيزةالعامة للمقاولات والاستثمارالعقارى | J38: EGS21541C015 | K38: مقاولات و إنشاءات هندسية | L38: عقارات
C39: SCFM | D39: مطاحن ومخابز جنوب القاهرة والجيزة | E39: #N/A | F39: SCFM | H39: الحديد والصلب المصرية | J39: EGS3D061C015 | K39: موارد أساسية | L39: مقاولات و إنشاءات هندسية
C40: SPIN | D40: الاسكندرية للغزل والنسيج (سبينالكس) | E40: سبينالكس | F40: SPIN | H40: الحديد والصلب للمناجم والمحاجر | J40: EGS102S1C014 | K40: موارد أساسية | L40: موارد أساسية
...
